Workbook

Sheet Readme
A1: SoleGuard - Simulated 10-Nurse Cohort
A2: Adaptive Smart Insole for Personalized Pressure and Temperature-Based Foot-Risk Monitoring in Long-Shift Nurses with Diabetes
A4: ALL DATA IN THIS WORKBOOK IS SIMULATED
A5: The insole hardware has not been built yet, so these 10 nurses are simulated by (data/generate_cohort_data.py, fixed random seed 7). They are NOT real patients and show that the method works on varied profiles, not that it works clinically. Replace the Readings sheet with real recordings once volunteers can be measured.
A7: HOW TO LOOK UP ONE NURSE
A8: 1 | B8: Open the 'Nurse Lookup' sheet (or see all nurses at once in 'Nurse Profiles').
A9: 2 | B9: Click the yellow cell (B3) and pick a nurse from the dropdown, for example NURSE-07.
A10: 3 | B10: The sheet shows the nurse's profile and condition, risk levels, and, for each signal, own normal, shift average and peak, and how far the nurse deviated.
A12: SHEETS
A13: Nurse Lookup | B13: Nurse Profiles lists all 10 nurses (name, age, gender, health conditions, results); Nurse Lookup shows one nurse in detail.
A14: Cohort Summary | B14: All 10 nurses in one table, with each nurse's own baseline, deviation counts, detected condition and a plain-language summary.
A15: Readings | B15: Every simulated reading (200 per nurse, one every 30 s). Z-scores are calculated by formula; risk levels come from the SoleGuard ML module.
A16: Clinical Reference | B16: Why this helps a nurse with diabetes, what can happen if readings are ignored, photo evidence slots, limits, and sources.
A18: KEY TERMS
A19: Baseline | B19: A nurse's own normal: the mean and standard deviation (SD) of each signal over the first 60 readings (30 min). Outliers are trimmed first.
A20: Deviation (SD) | B20: How many standard deviations a reading sits above THAT NURSE'S OWN baseline (a z-score). It is not compared with other nurses.
A21: Risk level | B21: normal: below 2 SD. caution: 2 to 3 SD. alert: 3 SD or more AND a second signal is also elevated, or high pressure after about 5 minutes of standing.
A22: Elevated (this sheet) | B22: A signal counts as 'Elevated' for a nurse when at least the number of readings in Cohort Summary D2 are 2 SD or more above that nurse's baseline.
A23: Calibration phase | B23: The first 60 readings are the learning phase; the system reports them as normal because the baseline is still being learned.
A25: CELL COLOURS
A26: Blue text | B26: A typed-in input or assumption (baselines and thresholds). Everything in black is a formula.
A27: Yellow cell | B27: The dropdown where you choose a nurse.
A29: ASSUMPTIONS AND SOURCES OF NUMBERS
A30: Baselines | B30: Calculated by the project's personalization.py module on each nurse's first 60 readings, then pasted in as values (blue).
A31: Risk levels | B31: Calculated by the same module (RiskDetector) on the live readings. Z-scores in the Readings sheet are recalculated here by formula from the baselines.
A32: Thresholds | B32: 2 SD and 3 SD are standard statistical conventions, not clinically tuned values. Pressure values are in raw sensor units.
A34: FICTIONAL PERSONAS
A35: Nurse Profiles | B35: Names, ages, genders and health details are invented for the simulation. Replace the blue cells on the Nurse Profiles sheet with real volunteers' details (with written consent) if real data is collected.

Sheet Nurse Profiles
A1: Nurse Profiles - 10 simulated nurses: who they are and what their readings show
A2: FICTIONAL PERSONAS. Names, ages and health details are invented for the simulation. Blue cells are inputs: replace them with real volunteers' details (with written consent) if real data is collected.
A3: Columns K to Q are formulas that read each nurse's own results from the Cohort Summary sheet.
A4: Nurse ID | B4: Name (fictional) | C4: Age | D4: Gender | E4: Ward | F4: Years in nursing | G4: Diabetes type | H4: Years with diabetes | I4: Foot sensation (neuropathy status) | J4: Other current health conditions | K4: Detected condition (from readings) | L4: Highest risk level | M4: Peak pressure deviation (SD) | N4: Peak temp deviation (SD) | O4: Caution readings | P4: Alert readings | Q4: Summary of deviations
A5: NURSE-01 | B5: Anitha D'Souza | C5: 34 | D5: Female | E5: Medical ward | F5: 9 | G5: Type 2 | H5: 4 | I5: Normal sensation | J5: None | K5: =INDEX('Cohort Summary'!$W$5:$W$14,MATCH($A5,'Cohort Summary'!$A$5:$A$14,0)) -> No signs | L5: =INDEX('Cohort Summary'!$Y$5:$Y$14,MATCH($A5,'Cohort Summary'!$A$5:$A$14,0)) -> normal | M5: =INDEX('Cohort Summary'!$S$5:$S$14,MATCH($A5,'Cohort Summary'!$A$5:$A$14,0)) -> 1.8588235 | N5: =INDEX('Cohort Summary'!$T$5:$T$14,MATCH($A5,'Cohort Summary'!$A$5:$A$14,0)) -> 1.9272727 | O5: =INDEX('Cohort Summary'!$N$5:$N$14,MATCH($A5,'Cohort Summary'!$A$5:$A$14,0)) -> 0 | P5: =INDEX('Cohort Summary'!$O$5:$O$14,MATCH($A5,'Cohort Summary'!$A$5:$A$14,0)) -> 0 | Q5: =INDEX('Cohort Summary'!$Z$5:$Z$14,MATCH($A5,'Cohort Summary'!$A$5:$A$14,0)) -> No meaningful deviation from own baseline during the live shift.
A6: NURSE-02 | B6: Rekha Shetty | C6: 41 | D6: Female | E6: Surgical ward | F6: 15 | G6: Type 2 | H6: 8 | I6: Early loss of sensation | J6: Hypertension | K6: =INDEX('Cohort Summary'!$W$5:$W$14,MATCH($A6,'Cohort Summary'!$A$5:$A$14,0)) -> Pressure only | L6: =INDEX('Cohort Summary'!$Y$5:$Y$14,MATCH($A6,'Cohort Summary'!$A$5:$A$14,0)) -> alert | M6: =INDEX('Cohort Summary'!$S$5:$S$14,MATCH($A6,'Cohort Summary'!$A$5:$A$14,0)) -> 5.2116564 | N6: =INDEX('Cohort Summary'!$T$5:$T$14,MATCH($A6,'Cohort Summary'!$A$5:$A$14,0)) -> 1.515625 | O6: =INDEX('Cohort Summary'!$N$5:$N$14,MATCH($A6,'Cohort Summary'!$A$5:$A$14,0)) -> 17 | P6: =INDEX('Cohort Summary'!$O$5:$O$14,MATCH($A6,'Cohort Summary'!$A$5:$A$14,0)) -> 3 | Q6: =INDEX('Cohort Summary'!$Z$5:$Z$14,MATCH($A6,'Cohort Summary'!$A$5:$A$14,0)) -> Deviation from own baseline: pressure peaked 5.2 SD above own normal (20 elevated readings). 3 alert and 17 caution readings.
A7: NURSE-03 | B7: Fathima Noor | C7: 38 | D7: Female | E7: ICU | F7: 12 | G7: Type 2 | H7: 6 | I7: Normal sensation | J7: None | K7: =INDEX('Cohort Summary'!$W$5:$W$14,MATCH($A7,'Cohort Summary'!$A$5:$A$14,0)) -> Temperature only | L7: =INDEX('Cohort Summary'!$Y$5:$Y$14,MATCH($A7,'Cohort Summary'!$A$5:$A$14,0)) -> caution | M7: =INDEX('Cohort Summary'!$S$5:$S$14,MATCH($A7,'Cohort Summary'!$A$5:$A$14,0)) -> 1.9205776 | N7: =INDEX('Cohort Summary'!$T$5:$T$14,MATCH($A7,'Cohort Summary'!$A$5:$A$14,0)) -> 6.0877193 | O7: =INDEX('Cohort Summary'!$N$5:$N$14,MATCH($A7,'Cohort Summary'!$A$5:$A$14,0)) -> 15 | P7: =INDEX('Cohort Summary'!$O$5:$O$14,MATCH($A7,'Cohort Summary'!$A$5:$A$14,0)) -> 0 | Q7: =INDEX('Cohort Summary'!$Z$5:$Z$14,MATCH($A7,'Cohort Summary'!$A$5:$A$14,0)) -> Deviation from own baseline: temperature peaked 6.1 SD above own normal (15 elevated readings). 0 alert and 15 caution readings.
A8: NURSE-04 | B8: Savitha Rao | C8: 49 | D8: Female | E8: Operation theatre | F8: 24 | G8: Type 2 | H8: 12 | I8: Confirmed neuropathy | J8: Hypertension, high cholesterol | K8: =INDEX('Cohort Summary'!$W$5:$W$14,MATCH($A8,'Cohort Summary'!$A$5:$A$14,0)) -> Both | L8: =INDEX('Cohort Summary'!$Y$5:$Y$14,MATCH($A8,'Cohort Summary'!$A$5:$A$14,0)) -> alert | M8: =INDEX('Cohort Summary'!$S$5:$S$14,MATCH($A8,'Cohort Summary'!$A$5:$A$14,0)) -> 5.7092652 | N8: =INDEX('Cohort Summary'!$T$5:$T$14,MATCH($A8,'Cohort Summary'!$A$5:$A$14,0)) -> 6.6896552 | O8: =INDEX('Cohort Summary'!$N$5:$N$14,MATCH($A8,'Cohort Summary'!$A$5:$A$14,0)) -> 3 | P8: =INDEX('Cohort Summary'!$O$5:$O$14,MATCH($A8,'Cohort Summary'!$A$5:$A$14,0)) -> 20 | Q8: =INDEX('Cohort Summary'!$Z$5:$Z$14,MATCH($A8,'Cohort Summary'!$A$5:$A$14,0)) -> Deviation from own baseline: pressure peaked 5.7 SD above own normal (23 elevated readings); temperature peaked 6.7 SD above own normal (21 elevated readings). 20 alert and 3 caution readings.
A9: NURSE-05 | B9: Joseph Pinto | C9: 45 | D9: Male | E9: Emergency | F9: 20 | G9: Type 2 | H9: 7 | I9: Normal sensation | J9: Overweight | K9: =INDEX('Cohort Summary'!$W$5:$W$14,MATCH($A9,'Cohort Summary'!$A$5:$A$14,0)) -> No signs | L9: =INDEX('Cohort Summary'!$Y$5:$Y$14,MATCH($A9,'Cohort Summary'!$A$5:$A$14,0)) -> normal | M9: =INDEX('Cohort Summary'!$S$5:$S$14,MATCH($A9,'Cohort Summary'!$A$5:$A$14,0)) -> 1.7224199 | N9: =INDEX('Cohort Summary'!$T$5:$T$14,MATCH($A9,'Cohort Summary'!$A$5:$A$14,0)) -> 1.7142857 | O9: =INDEX('Cohort Summary'!$N$5:$N$14,MATCH($A9,'Cohort Summary'!$A$5:$A$14,0)) -> 0 | P9: =INDEX('Cohort Summary'!$O$5:$O$14,MATCH($A9,'Cohort Summary'!$A$5:$A$14,0)) -> 0 | Q9: =INDEX('Cohort Summary'!$Z$5:$Z$14,MATCH($A9,'Cohort Summary'!$A$5:$A$14,0)) -> No meaningful deviation from own baseline during the live shift.
A10: NURSE-06 | B10: Deepa Nayak | C10: 36 | D10: Female | E10: Paediatric ward | F10: 11 | G10: Type 1 | H10: 15 | I10: Early loss of sensation | J10: None | K10: =INDEX('Cohort Summary'!$W$5:$W$14,MATCH($A10,'Cohort Summary'!$A$5:$A$14,0)) -> Pressure only | L10: =INDEX('Cohort Summary'!$Y$5:$Y$14,MATCH($A10,'Cohort Summary'!$A$5:$A$14,0)) -> alert | M10: =INDEX('Cohort Summary'!$S$5:$S$14,MATCH($A10,'Cohort Summary'!$A$5:$A$14,0)) -> 5.1493056 | N10: =INDEX('Cohort Summary'!$T$5:$T$14,MATCH($A10,'Cohort Summary'!$A$5:$A$14,0)) -> 1.8703704 | O10: =INDEX('Cohort Summary'!$N$5:$N$14,MATCH($A10,'Cohort Summary'!$A$5:$A$14,0)) -> 15 | P10: =INDEX('Cohort Summary'!$O$5:$O$14,MATCH($A10,'Cohort Summary'!$A$5:$A$14,0)) -> 3 | Q10: =INDEX('Cohort Summary'!$Z$5:$Z$14,MATCH($A10,'Cohort Summary'!$A$5:$A$14,0)) -> Deviation from own baseline: pressure peaked 5.1 SD above own normal (18 elevated readings). 3 alert and 15 caution readings.
A11: NURSE-07 | B11: Lakshmi Bhat | C11: 52 | D11: Female | E11: ICU | F11: 28 | G11: Type 2 | H11: 14 | I11: Confirmed neuropathy | J11: Hypertension, varicose veins | K11: =INDEX('Cohort Summary'!$W$5:$W$14,MATCH($A11,'Cohort Summary'!$A$5:$A$14,0)) -> Both | L11: =INDEX('Cohort Summary'!$Y$5:$Y$14,MATCH($A11,'Cohort Summary'!$A$5:$A$14,0)) -> alert | M11: =INDEX('Cohort Summary'!$S$5:$S$14,MATCH($A11,'Cohort Summary'!$A$5:$A$14,0)) -> 6.4013841 | N11: =INDEX('Cohort Summary'!$T$5:$T$14,MATCH($A11,'Cohort Summary'!$A$5:$A$14,0)) -> 6.295082 | O11: =INDEX('Cohort Summary'!$N$5:$N$14,MATCH($A11,'Cohort Summary'!$A$5:$A$14,0)) -> 3 | P11: =INDEX('Cohort Summary'!$O$5:$O$14,MATCH($A11,'Cohort Summary'!$A$5:$A$14,0)) -> 44 | Q11: =INDEX('Cohort Summary'!$Z$5:$Z$14,MATCH($A11,'Cohort Summary'!$A$5:$A$14,0)) -> Deviation from own baseline: pressure peaked 6.4 SD above own normal (47 elevated readings); temperature peaked 6.3 SD above own normal (44 elevated readings). 44 alert and 3 caution readings.
A12: NURSE-08 | B12: Mohammed Rafiq | C12: 31 | D12: Male | E12: Medical ward | F12: 6 | G12: Type 1 | H12: 3 | I12: Normal sensation | J12: None | K12: =INDEX('Cohort Summary'!$W$5:$W$14,MATCH($A12,'Cohort Summary'!$A$5:$A$14,0)) -> No signs | L12: =INDEX('Cohort Summary'!$Y$5:$Y$14,MATCH($A12,'Cohort Summary'!$A$5:$A$14,0)) -> normal | M12: =INDEX('Cohort Summary'!$S$5:$S$14,MATCH($A12,'Cohort Summary'!$A$5:$A$14,0)) -> 1.7785714 | N12: =INDEX('Cohort Summary'!$T$5:$T$14,MATCH($A12,'Cohort Summary'!$A$5:$A$14,0)) -> 1.7068966 | O12: =INDEX('Cohort Summary'!$N$5:$N$14,MATCH($A12,'Cohort Summary'!$A$5:$A$14,0)) -> 0 | P12: =INDEX('Cohort Summary'!$O$5:$O$14,MATCH($A12,'Cohort Summary'!$A$5:$A$14,0)) -> 0 | Q12: =INDEX('Cohort Summary'!$Z$5:$Z$14,MATCH($A12,'Cohort Summary'!$A$5:$A$14,0)) -> No meaningful deviation from own baseline during the live shift.
A13: NURSE-09 | B13: Prema Kumari | C13: 47 | D13: Female | E13: Maternity ward | F13: 22 | G13: Type 2 | H13: 9 | I13: Normal sensation | J13: Hypothyroidism | K13: =INDEX('Cohort Summary'!$W$5:$W$14,MATCH($A13,'Cohort Summary'!$A$5:$A$14,0)) -> Temperature only | L13: =INDEX('Cohort Summary'!$Y$5:$Y$14,MATCH($A13,'Cohort Summary'!$A$5:$A$14,0)) -> caution | M13: =INDEX('Cohort Summary'!$S$5:$S$14,MATCH($A13,'Cohort Summary'!$A$5:$A$14,0)) -> 1.970297 | N13: =INDEX('Cohort Summary'!$T$5:$T$14,MATCH($A13,'Cohort Summary'!$A$5:$A$14,0)) -> 5.7704918 | O13: =INDEX('Cohort Summary'!$N$5:$N$14,MATCH($A13,'Cohort Summary'!$A$5:$A$14,0)) -> 55 | P13: =INDEX('Cohort Summary'!$O$5:$O$14,MATCH($A13,'Cohort Summary'!$A$5:$A$14,0)) -> 0 | Q13: =INDEX('Cohort Summary'!$Z$5:$Z$14,MATCH($A13,'Cohort Summary'!$A$5:$A$14,0)) -> Deviation from own baseline: temperature peaked 5.8 SD above own normal (55 elevated readings). 0 alert and 55 caution readings.
A14: NURSE-10 | B14: Sunitha George | C14: 43 | D14: Female | E14: Surgical ward | F14: 18 | G14: Type 2 | H14: 10 | I14: Early loss of sensation | J14: Hypertension | K14: =INDEX('Cohort Summary'!$W$5:$W$14,MATCH($A14,'Cohort Summary'!$A$5:$A$14,0)) -> Both | L14: =INDEX('Cohort Summary'!$Y$5:$Y$14,MATCH($A14,'Cohort Summary'!$A$5:$A$14,0)) -> alert | M14: =INDEX('Cohort Summary'!$S$5:$S$14,MATCH($A14,'Cohort Summary'!$A$5:$A$14,0)) -> 4.0487805 | N14: =INDEX('Cohort Summary'!$T$5:$T$14,MATCH($A14,'Cohort Summary'!$A$5:$A$14,0)) -> 3.9322034 | O14: =INDEX('Cohort Summary'!$N$5:$N$14,MATCH($A14,'Cohort Summary'!$A$5:$A$14,0)) -> 7 | P14: =INDEX('Cohort Summary'!$O$5:$O$14,MATCH($A14,'Cohort Summary'!$A$5:$A$14,0)) -> 11 | Q14: =INDEX('Cohort Summary'!$Z$5:$Z$14,MATCH($A14,'Cohort Summary'!$A$5:$A$14,0)) -> Deviation from own baseline: pressure peaked 4.0 SD above own normal (17 elevated readings); temperature peaked 3.9 SD above own normal (13 elevated readings). 11 alert and 7 caution readings.

Sheet Nurse Lookup
A1: Nurse Lookup - pick a nurse to see the profile, conditions and deviations
A2: SIMULATED DATA, FICTIONAL PERSONAS. Every deviation is measured against that nurse's OWN baseline, not against other nurses.
A3: Select nurse > | B3: NURSE-07 | C3: (click the yellow cell and choose from the dropdown)
A4: Name (fictional) | B4: =INDEX('Nurse Profiles'!$B$5:$B$14,MATCH($B$3,'Nurse Profiles'!$A$5:$A$14,0)) -> Lakshmi Bhat
A5: Age | B5: =INDEX('Nurse Profiles'!$C$5:$C$14,MATCH($B$3,'Nurse Profiles'!$A$5:$A$14,0)) -> 52
A6: Gender | B6: =INDEX('Nurse Profiles'!$D$5:$D$14,MATCH($B$3,'Nurse Profiles'!$A$5:$A$14,0)) -> Female
A7: Ward and experience | B7: =INDEX('Nurse Profiles'!$E$5:$E$14,MATCH($B$3,'Nurse Profiles'!$A$5:$A$14,0))&", "&INDEX('Nurse Profiles'!$F$5:$F$14,MATCH($B$3,'Nurse Profiles'!$A$5:$A$14,0))&" years in nursing" -> ICU, 28 years in nursing
A8: Diabetes | B8: =INDEX('Nurse Profiles'!$G$5:$G$14,MATCH($B$3,'Nurse Profiles'!$A$5:$A$14,0))&" diabetes for "&INDEX('Nurse Profiles'!$H$5:$H$14,MATCH($B$3,'Nurse Profiles'!$A$5:$A$14,0))&" years" -> Type 2 diabetes for 14 years
A9: Foot sensation (neuropathy) | B9: =INDEX('Nurse Profiles'!$I$5:$I$14,MATCH($B$3,'Nurse Profiles'!$A$5:$A$14,0)) -> Confirmed neuropathy
A10: Other current health conditions | B10: =INDEX('Nurse Profiles'!$J$5:$J$14,MATCH($B$3,'Nurse Profiles'!$A$5:$A$14,0)) -> Hypertension, varicose veins
A12: Designed pattern (simulated) | B12: =INDEX('Cohort Summary'!$B$5:$B$14,MATCH($B$3,'Cohort Summary'!$A$5:$A$14,0)) -> Long standing stretches with pressure and temperature rising together
A13: Detected condition | B13: =INDEX('Cohort Summary'!$W$5:$W$14,MATCH($B$3,'Cohort Summary'!$A$5:$A$14,0)) -> Both
A14: Highest risk level in live shift | B14: =INDEX('Cohort Summary'!$Y$5:$Y$14,MATCH($B$3,'Cohort Summary'!$A$5:$A$14,0)) -> alert
A15: Summary of deviations | B15: =INDEX('Cohort Summary'!$Z$5:$Z$14,MATCH($B$3,'Cohort Summary'!$A$5:$A$14,0)) -> Deviation from own baseline: pressure peaked 6.4 SD above own normal (47 elevated readings); temperature peaked 6.3 SD above own normal (44 elevated readings). 44 alert and 3 caution readings.
A17: Live-phase readings | B17: =INDEX('Cohort Summary'!$L$5:$L$14,MATCH($B$3,'Cohort Summary'!$A$5:$A$14,0)) -> 140
A18: Normal | B18: =INDEX('Cohort Summary'!$M$5:$M$14,MATCH($B$3,'Cohort Summary'!$A$5:$A$14,0)) -> 93
A19: Caution | B19: =INDEX('Cohort Summary'!$N$5:$N$14,MATCH($B$3,'Cohort Summary'!$A$5:$A$14,0)) -> 3
A20: Alert | B20: =INDEX('Cohort Summary'!$O$5:$O$14,MATCH($B$3,'Cohort Summary'!$A$5:$A$14,0)) -> 44
A21: % of live readings flagged | B21: =INDEX('Cohort Summary'!$P$5:$P$14,MATCH($B$3,'Cohort Summary'!$A$5:$A$14,0)) -> 0.33571429
A22: First caution at | B22: =IFERROR(INDEX(Readings!$B$2:$B$2001,MATCH($B$3&"|caution",Readings!$P$2:$P$2001,0)),"none this shift") -> 46303.314
A23: First alert at | B23: =IFERROR(INDEX(Readings!$B$2:$B$2001,MATCH($B$3&"|alert",Readings!$P$2:$P$2001,0)),"none this shift") -> 46303.314
A26: Signal | B26: Baseline mean (own normal) | C26: Baseline SD | D26: Shift average (live) | E26: Shift peak (live) | F26: Peak deviation (SD above own baseline) | G26: Readings 2+ SD above baseline | H26: % of live readings | I26: Status
A27: Heel pressure | B27: =INDEX('Cohort Summary'!$D$5:$D$14,MATCH($B$3,'Cohort Summary'!$A$5:$A$14,0)) -> 48 | C27: =INDEX('Cohort Summary'!$E$5:$E$14,MATCH($B$3,'Cohort Summary'!$A$5:$A$14,0)) -> 2.89 | D27: =AVERAGEIFS(Readings!$D$2:$D$2001,Readings!$A$2:$A$2001,$B$3,Readings!$C$2:$C$2001,"Live") -> 52.213571 | E27: =_xlfn.MAXIFS(Readings!$D$2:$D$2001,Readings!$A$2:$A$2001,$B$3,Readings!$C$2:$C$2001,"Live") -> 66.5 | F27: =(E27-B27)/C27 -> 6.4013841 | G27: =COUNTIFS(Readings!$A$2:$A$2001,$B$3,Readings!$C$2:$C$2001,"Live",Readings!$I$2:$I$2001,">="&'Cohort Summary'!$B$2) -> 44 | H27: =IF($B$17=0,0,G27/$B$17) -> 0.31428571 | I27: =IF(G27>='Cohort Summary'!$D$2,"ELEVATED","Normal") -> ELEVATED
A28: Midfoot pressure | B28: =INDEX('Cohort Summary'!$F$5:$F$14,MATCH($B$3,'Cohort Summary'!$A$5:$A$14,0)) -> 18.45 | C28: =INDEX('Cohort Summary'!$G$5:$G$14,MATCH($B$3,'Cohort Summary'!$A$5:$A$14,0)) -> 1.91 | D28: =AVERAGEIFS(Readings!$E$2:$E$2001,Readings!$A$2:$A$2001,$B$3,Readings!$C$2:$C$2001,"Live") -> 18.386429 | E28: =_xlfn.MAXIFS(Readings!$E$2:$E$2001,Readings!$A$2:$A$2001,$B$3,Readings!$C$2:$C$2001,"Live") -> 21.9 | F28: =(E28-B28)/C28 -> 1.8062827 | G28: =COUNTIFS(Readings!$A$2:$A$2001,$B$3,Readings!$C$2:$C$2001,"Live",Readings!$J$2:$J$2001,">="&'Cohort Summary'!$B$2) -> 0 | H28: =IF($B$17=0,0,G28/$B$17) -> 0 | I28: =IF(G28>='Cohort Summary'!$D$2,"ELEVATED","Normal") -> Normal
A29: Toe pressure | B29: =INDEX('Cohort Summary'!$H$5:$H$14,MATCH($B$3,'Cohort Summary'!$A$5:$A$14,0)) -> 34.58 | C29: =INDEX('Cohort Summary'!$I$5:$I$14,MATCH($B$3,'Cohort Summary'!$A$5:$A$14,0)) -> 2.63 | D29: =AVERAGEIFS(Readings!$F$2:$F$2001,Readings!$A$2:$A$2001,$B$3,Readings!$C$2:$C$2001,"Live") -> 38.080714 | E29: =_xlfn.MAXIFS(Readings!$F$2:$F$2001,Readings!$A$2:$A$2001,$B$3,Readings!$C$2:$C$2001,"Live") -> 50.7 | F29: =(E29-B29)/C29 -> 6.1292776 | G29: =COUNTIFS(Readings!$A$2:$A$2001,$B$3,Readings!$C$2:$C$2001,"Live",Readings!$K$2:$K$2001,">="&'Cohort Summary'!$B$2) -> 44 | H29: =IF($B$17=0,0,G29/$B$17) -> 0.31428571 | I29: =IF(G29>='Cohort Summary'!$D$2,"ELEVATED","Normal") -> ELEVATED
A30: Foot temperature (°C) | B30: =INDEX('Cohort Summary'!$J$5:$J$14,MATCH($B$3,'Cohort Summary'!$A$5:$A$14,0)) -> 33.46 | C30: =INDEX('Cohort Summary'!$K$5:$K$14,MATCH($B$3,'Cohort Summary'!$A$5:$A$14,0)) -> 0.61 | D30: =AVERAGEIFS(Readings!$G$2:$G$2001,Readings!$A$2:$A$2001,$B$3,Readings!$C$2:$C$2001,"Live") -> 34.199286 | E30: =_xlfn.MAXIFS(Readings!$G$2:$G$2001,Readings!$A$2:$A$2001,$B$3,Readings!$C$2:$C$2001,"Live") -> 37.3 | F30: =(E30-B30)/C30 -> 6.295082 | G30: =COUNTIFS(Readings!$A$2:$A$2001,$B$3,Readings!$C$2:$C$2001,"Live",Readings!$L$2:$L$2001,">="&'Cohort Summary'!$B$2) -> 44 | H30: =IF($B$17=0,0,G30/$B$17) -> 0.31428571 | I30: =IF(G30>='Cohort Summary'!$D$2,"ELEVATED","Normal") -> ELEVATED
A32: How to read this
A33: A nurse's baseline is what is normal FOR THAT NURSE (learned from the first 30 minutes of the shift). A deviation of 2 SD or more is unusual for them; 3 SD or more is very unusual. A signal shows ELEVATED when enough readings (Cohort Summary D2) reach 2 SD. 'Detected condition' combines the pressure signals and temperature: both, one, or none. Pressure is in raw sensor units.

Sheet Cohort Summary
A1: Cohort Summary - 10 simulated nurses (each compared only with their own baseline)
A2: Elevated if deviation (SD) >= | B2: 2 | C2: Min elevated readings to flag a condition: | D2: 3 | E2: (assumptions - change them and every status below updates)
A3: SIMULATED DATA. Baselines (blue) come from the ML module; everything else is a formula over the Readings sheet (live phase only).
A4: Nurse ID | B4: Designed pattern (simulated) | C4: Designed category | D4: Heel baseline mean | E4: Heel baseline SD | F4: Midfoot baseline mean | G4: Midfoot baseline SD | H4: Toe baseline mean | I4: Toe baseline SD | J4: Temp baseline mean (°C) | K4: Temp baseline SD (°C) | L4: Live readings | M4: Normal | N4: Caution | O4: Alert | P4: % flagged | Q4: Pressure-elevated readings | R4: Temp-elevated readings | S4: Peak pressure deviation (SD) | T4: Peak temp deviation (SD) | U4: Pressure status | V4: Temperature status | W4: Detected category | X4: Matches design? | Y4: Highest risk level | Z4: Plain-language summary
A5: NURSE-01 | B5: Stable all shift, stays within own normal | C5: No signs | D5: 40.03 | E5: 3.11 | F5: 18.53 | G5: 1.94 | H5: 30.26 | I5: 2.55 | J5: 32.94 | K5: 0.55 | L5: =COUNTIFS(Readings!$A$2:$A$2001,$A5,Readings!$C$2:$C$2001,"Live") -> 140 | M5: =COUNTIFS(Readings!$A$2:$A$2001,$A5,Readings!$C$2:$C$2001,"Live",Readings!$N$2:$N$2001,"normal") -> 140 | N5: =COUNTIFS(Readings!$A$2:$A$2001,$A5,Readings!$C$2:$C$2001,"Live",Readings!$N$2:$N$2001,"caution") -> 0 | O5: =COUNTIFS(Readings!$A$2:$A$2001,$A5,Readings!$C$2:$C$2001,"Live",Readings!$N$2:$N$2001,"alert") -> 0 | P5: =IF(L5=0,0,(N5+O5)/L5) -> 0 | Q5: =COUNTIFS(Readings!$A$2:$A$2001,$A5,Readings!$C$2:$C$2001,"Live",Readings!$M$2:$M$2001,">="&$B$2) -> 0 | R5: =COUNTIFS(Readings!$A$2:$A$2001,$A5,Readings!$C$2:$C$2001,"Live",Readings!$L$2:$L$2001,">="&$B$2) -> 0 | S5: =_xlfn.MAXIFS(Readings!$M$2:$M$2001,Readings!$A$2:$A$2001,$A5,Readings!$C$2:$C$2001,"Live") -> 1.8588235 | T5: =_xlfn.MAXIFS(Readings!$L$2:$L$2001,Readings!$A$2:$A$2001,$A5,Readings!$C$2:$C$2001,"Live") -> 1.9272727 | U5: =IF(Q5>=$D$2,"Elevated","Normal") -> Normal | V5: =IF(R5>=$D$2,"Elevated","Normal") -> Normal | W5: =IF(AND(U5="Elevated",V5="Elevated"),"Both",IF(U5="Elevated","Pressure only",IF(V5="Elevated","Temperature only","No signs"))) -> No signs | X5: =IF(W5=C5,"Yes","CHECK") -> Yes | Y5: =IF(O5>0,"alert",IF(N5>0,"caution","normal")) -> normal | Z5: =IF(W5="No signs","No meaningful deviation from own baseline during the live shift.","Deviation from own baseline: "&IF(U5="Elevated","pressure peaked "&TEXT(S5,"0.0")&" SD above own normal ("&Q5&" elevated readings)","")&IF(AND(U5="Elevated",V5="Elevated"),"; ","")&IF(V5="Elevated","temperature peaked "&TEXT(T5,"0.0")&" SD above own normal ("&R5&" elevated readings)","")&". "&O5&" alert and "&N5&" caution readings.") -> No meaningful deviation from own baseline during the live shift.
A6: NURSE-02 | B6: Heel pressure rises after long standing; temperature normal | C6: Pressure only | D6: 43.81 | E6: 3.26 | F6: 19.05 | G6: 2.12 | H6: 32.45 | I6: 2.94 | J6: 32.83 | K6: 0.64 | L6: =COUNTIFS(Readings!$A$2:$A$2001,$A6,Readings!$C$2:$C$2001,"Live") -> 140 | M6: =COUNTIFS(Readings!$A$2:$A$2001,$A6,Readings!$C$2:$C$2001,"Live",Readings!$N$2:$N$2001,"normal") -> 120 | N6: =COUNTIFS(Readings!$A$2:$A$2001,$A6,Readings!$C$2:$C$2001,"Live",Readings!$N$2:$N$2001,"caution") -> 17 | O6: =COUNTIFS(Readings!$A$2:$A$2001,$A6,Readings!$C$2:$C$2001,"Live",Readings!$N$2:$N$2001,"alert") -> 3 | P6: =IF(L6=0,0,(N6+O6)/L6) -> 0.14285714 | Q6: =COUNTIFS(Readings!$A$2:$A$2001,$A6,Readings!$C$2:$C$2001,"Live",Readings!$M$2:$M$2001,">="&$B$2) -> 20 | R6: =COUNTIFS(Readings!$A$2:$A$2001,$A6,Readings!$C$2:$C$2001,"Live",Readings!$L$2:$L$2001,">="&$B$2) -> 0 | S6: =_xlfn.MAXIFS(Readings!$M$2:$M$2001,Readings!$A$2:$A$2001,$A6,Readings!$C$2:$C$2001,"Live") -> 5.2116564 | T6: =_xlfn.MAXIFS(Readings!$L$2:$L$2001,Readings!$A$2:$A$2001,$A6,Readings!$C$2:$C$2001,"Live") -> 1.515625 | U6: =IF(Q6>=$D$2,"Elevated","Normal") -> Elevated | V6: =IF(R6>=$D$2,"Elevated","Normal") -> Normal | W6: =IF(AND(U6="Elevated",V6="Elevated"),"Both",IF(U6="Elevated","Pressure only",IF(V6="Elevated","Temperature only","No signs"))) -> Pressure only | X6: =IF(W6=C6,"Yes","CHECK") -> Yes | Y6: =IF(O6>0,"alert",IF(N6>0,"caution","normal")) -> alert | Z6: =IF(W6="No signs","No meaningful deviation from own baseline during the live shift.","Deviation from own baseline: "&IF(U6="Elevated","pressure peaked "&TEXT(S6,"0.0")&" SD above own normal ("&Q6&" elevated readings)","")&IF(AND(U6="Elevated",V6="Elevated"),"; ","")&IF(V6="Elevated","temperature peaked "&TEXT(T6,"0.0")&" SD above own normal ("&R6&" elevated readings)","")&". "&O6&" alert and "&N6&" caution readings.") -> Deviation from own baseline: pressure peaked 5.2 SD above own normal (20 elevated readings). 3 alert and 17 caution readings.
A7: NURSE-03 | B7: Foot temperature rises in short hot-spot episodes; pressure normal | C7: Temperature only | D7: 36.96 | E7: 2.8 | F7: 18.28 | G7: 2.17 | H7: 27.68 | I7: 2.77 | J7: 33.33 | K7: 0.57 | L7: =COUNTIFS(Readings!$A$2:$A$2001,$A7,Readings!$C$2:$C$2001,"Live") -> 140 | M7: =COUNTIFS(Readings!$A$2:$A$2001,$A7,Readings!$C$2:$C$2001,"Live",Readings!$N$2:$N$2001,"normal") -> 125 | N7: =COUNTIFS(Readings!$A$2:$A$2001,$A7,Readings!$C$2:$C$2001,"Live",Readings!$N$2:$N$2001,"caution") -> 15 | O7: =COUNTIFS(Readings!$A$2:$A$2001,$A7,Readings!$C$2:$C$2001,"Live",Readings!$N$2:$N$2001,"alert") -> 0 | P7: =IF(L7=0,0,(N7+O7)/L7) -> 0.10714286 | Q7: =COUNTIFS(Readings!$A$2:$A$2001,$A7,Readings!$C$2:$C$2001,"Live",Readings!$M$2:$M$2001,">="&$B$2) -> 0 | R7: =COUNTIFS(Readings!$A$2:$A$2001,$A7,Readings!$C$2:$C$2001,"Live",Readings!$L$2:$L$2001,">="&$B$2) -> 15 | S7: =_xlfn.MAXIFS(Readings!$M$2:$M$2001,Readings!$A$2:$A$2001,$A7,Readings!$C$2:$C$2001,"Live") -> 1.9205776 | T7: =_xlfn.MAXIFS(Readings!$L$2:$L$2001,Readings!$A$2:$A$2001,$A7,Readings!$C$2:$C$2001,"Live") -> 6.0877193 | U7: =IF(Q7>=$D$2,"Elevated","Normal") -> Normal | V7: =IF(R7>=$D$2,"Elevated","Normal") -> Elevated | W7: =IF(AND(U7="Elevated",V7="Elevated"),"Both",IF(U7="Elevated","Pressure only",IF(V7="Elevated","Temperature only","No signs"))) -> Temperature only | X7: =IF(W7=C7,"Yes","CHECK") -> Yes | Y7: =IF(O7>0,"alert",IF(N7>0,"caution","normal")) -> caution | Z7: =IF(W7="No signs","No meaningful deviation from own baseline during the live shift.","Deviation from own baseline: "&IF(U7="Elevated","pressure peaked "&TEXT(S7,"0.0")&" SD above own normal ("&Q7&" elevated readings)","")&IF(AND(U7="Elevated",V7="Elevated"),"; ","")&IF(V7="Elevated","temperature peaked "&TEXT(T7,"0.0")&" SD above own normal ("&R7&" elevated readings)","")&". "&O7&" alert and "&N7&" caution readings.") -> Deviation from own baseline: temperature peaked 6.1 SD above own normal (15 elevated readings). 0 alert and 15 caution readings.
A8: NURSE-04 | B8: Pressure and temperature both rise, repeatedly | C8: Both | D8: 45.83 | E8: 3.13 | F8: 19.64 | G8: 1.93 | H8: 33.15 | I8: 2.98 | J8: 33.32 | K8: 0.58 | L8: =COUNTIFS(Readings!$A$2:$A$2001,$A8,Readings!$C$2:$C$2001,"Live") -> 140 | M8: =COUNTIFS(Readings!$A$2:$A$2001,$A8,Readings!$C$2:$C$2001,"Live",Readings!$N$2:$N$2001,"normal") -> 117 | N8: =COUNTIFS(Readings!$A$2:$A$2001,$A8,Readings!$C$2:$C$2001,"Live",Readings!$N$2:$N$2001,"caution") -> 3 | O8: =COUNTIFS(Readings!$A$2:$A$2001,$A8,Readings!$C$2:$C$2001,"Live",Readings!$N$2:$N$2001,"alert") -> 20 | P8: =IF(L8=0,0,(N8+O8)/L8) -> 0.16428571 | Q8: =COUNTIFS(Readings!$A$2:$A$2001,$A8,Readings!$C$2:$C$2001,"Live",Readings!$M$2:$M$2001,">="&$B$2) -> 23 | R8: =COUNTIFS(Readings!$A$2:$A$2001,$A8,Readings!$C$2:$C$2001,"Live",Readings!$L$2:$L$2001,">="&$B$2) -> 21 | S8: =_xlfn.MAXIFS(Readings!$M$2:$M$2001,Readings!$A$2:$A$2001,$A8,Readings!$C$2:$C$2001,"Live") -> 5.7092652 | T8: =_xlfn.MAXIFS(Readings!$L$2:$L$2001,Readings!$A$2:$A$2001,$A8,Readings!$C$2:$C$2001,"Live") -> 6.6896552 | U8: =IF(Q8>=$D$2,"Elevated","Normal") -> Elevated | V8: =IF(R8>=$D$2,"Elevated","Normal") -> Elevated | W8: =IF(AND(U8="Elevated",V8="Elevated"),"Both",IF(U8="Elevated","Pressure only",IF(V8="Elevated","Temperature only","No signs"))) -> Both | X8: =IF(W8=C8,"Yes","CHECK") -> Yes | Y8: =IF(O8>0,"alert",IF(N8>0,"caution","normal")) -> alert | Z8: =IF(W8="No signs","No meaningful deviation from own baseline during the live shift.","Deviation from own baseline: "&IF(U8="Elevated","pressure peaked "&TEXT(S8,"0.0")&" SD above own normal ("&Q8&" elevated readings)","")&IF(AND(U8="Elevated",V8="Elevated"),"; ","")&IF(V8="Elevated","temperature peaked "&TEXT(T8,"0.0")&" SD above own normal ("&R8&" elevated readings)","")&". "&O8&" alert and "&N8&" caution readings.") -> Deviation from own baseline: pressure peaked 5.7 SD above own normal (23 elevated readings); temperature peaked 6.7 SD above own normal (21 elevated readings). 20 alert and 3 caution readings.
A9: NURSE-05 | B9: High readings by other nurses' standards, but normal and stable for this nurse | C9: No signs | D9: 65.42 | E9: 2.88 | F9: 20.9 | G9: 2.16 | H9: 50.16 | I9: 2.81 | J9: 34.42 | K9: 0.63 | L9: =COUNTIFS(Readings!$A$2:$A$2001,$A9,Readings!$C$2:$C$2001,"Live") -> 140 | M9: =COUNTIFS(Readings!$A$2:$A$2001,$A9,Readings!$C$2:$C$2001,"Live",Readings!$N$2:$N$2001,"normal") -> 140 | N9: =COUNTIFS(Readings!$A$2:$A$2001,$A9,Readings!$C$2:$C$2001,"Live",Readings!$N$2:$N$2001,"caution") -> 0 | O9: =COUNTIFS(Readings!$A$2:$A$2001,$A9,Readings!$C$2:$C$2001,"Live",Readings!$N$2:$N$2001,"alert") -> 0 | P9: =IF(L9=0,0,(N9+O9)/L9) -> 0 | Q9: =COUNTIFS(Readings!$A$2:$A$2001,$A9,Readings!$C$2:$C$2001,"Live",Readings!$M$2:$M$2001,">="&$B$2) -> 0 | R9: =COUNTIFS(Readings!$A$2:$A$2001,$A9,Readings!$C$2:$C$2001,"Live",Readings!$L$2:$L$2001,">="&$B$2) -> 0 | S9: =_xlfn.MAXIFS(Readings!$M$2:$M$2001,Readings!$A$2:$A$2001,$A9,Readings!$C$2:$C$2001,"Live") -> 1.7224199 | T9: =_xlfn.MAXIFS(Readings!$L$2:$L$2001,Readings!$A$2:$A$2001,$A9,Readings!$C$2:$C$2001,"Live") -> 1.7142857 | U9: =IF(Q9>=$D$2,"Elevated","Normal") -> Normal | V9: =IF(R9>=$D$2,"Elevated","Normal") -> Normal | W9: =IF(AND(U9="Elevated",V9="Elevated"),"Both",IF(U9="Elevated","Pressure only",IF(V9="Elevated","Temperature only","No signs"))) -> No signs | X9: =IF(W9=C9,"Yes","CHECK") -> Yes | Y9: =IF(O9>0,"alert",IF(N9>0,"caution","normal")) -> normal | Z9: =IF(W9="No signs","No meaningful deviation from own baseline during the live shift.","Deviation from own baseline: "&IF(U9="Elevated","pressure peaked "&TEXT(S9,"0.0")&" SD above own normal ("&Q9&" elevated readings)","")&IF(AND(U9="Elevated",V9="Elevated"),"; ","")&IF(V9="Elevated","temperature peaked "&TEXT(T9,"0.0")&" SD above own normal ("&R9&" elevated readings)","")&". "&O9&" alert and "&N9&" caution readings.") -> No meaningful deviation from own baseline during the live shift.
A10: NURSE-06 | B10: Toe (forefoot) pressure rises, mostly while standing; temperature normal | C10: Pressure only | D10: 42.22 | E10: 2.92 | F10: 21.72 | G10: 2.06 | H10: 29.17 | I10: 2.88 | J10: 32.89 | K10: 0.54 | L10: =COUNTIFS(Readings!$A$2:$A$2001,$A10,Readings!$C$2:$C$2001,"Live") -> 140 | M10: =COUNTIFS(Readings!$A$2:$A$2001,$A10,Readings!$C$2:$C$2001,"Live",Readings!$N$2:$N$2001,"normal") -> 122 | N10: =COUNTIFS(Readings!$A$2:$A$2001,$A10,Readings!$C$2:$C$2001,"Live",Readings!$N$2:$N$2001,"caution") -> 15 | O10: =COUNTIFS(Readings!$A$2:$A$2001,$A10,Readings!$C$2:$C$2001,"Live",Readings!$N$2:$N$2001,"alert") -> 3 | P10: =IF(L10=0,0,(N10+O10)/L10) -> 0.12857143 | Q10: =COUNTIFS(Readings!$A$2:$A$2001,$A10,Readings!$C$2:$C$2001,"Live",Readings!$M$2:$M$2001,">="&$B$2) -> 18 | R10: =COUNTIFS(Readings!$A$2:$A$2001,$A10,Readings!$C$2:$C$2001,"Live",Readings!$L$2:$L$2001,">="&$B$2) -> 0 | S10: =_xlfn.MAXIFS(Readings!$M$2:$M$2001,Readings!$A$2:$A$2001,$A10,Readings!$C$2:$C$2001,"Live") -> 5.1493056 | T10: =_xlfn.MAXIFS(Readings!$L$2:$L$2001,Readings!$A$2:$A$2001,$A10,Readings!$C$2:$C$2001,"Live") -> 1.8703704 | U10: =IF(Q10>=$D$2,"Elevated","Normal") -> Elevated | V10: =IF(R10>=$D$2,"Elevated","Normal") -> Normal | W10: =IF(AND(U10="Elevated",V10="Elevated"),"Both",IF(U10="Elevated","Pressure only",IF(V10="Elevated","Temperature only","No signs"))) -> Pressure only | X10: =IF(W10=C10,"Yes","CHECK") -> Yes | Y10: =IF(O10>0,"alert",IF(N10>0,"caution","normal")) -> alert | Z10: =IF(W10="No signs","No meaningful deviation from own baseline during the live shift.","Deviation from own baseline: "&IF(U10="Elevated","pressure peaked "&TEXT(S10,"0.0")&" SD above own normal ("&Q10&" elevated readings)","")&IF(AND(U10="Elevated",V10="Elevated"),"; ","")&IF(V10="Elevated","temperature peaked "&TEXT(T10,"0.0")&" SD above own normal ("&R10&" elevated readings)","")&". "&O10&" alert and "&N10&" caution readings.") -> Deviation from own baseline: pressure peaked 5.1 SD above own normal (18 elevated readings). 3 alert and 15 caution readings.
A11: NURSE-07 | B11: Long standing stretches with pressure and temperature rising together | C11: Both | D11: 48 | E11: 2.89 | F11: 18.45 | G11: 1.91 | H11: 34.58 | I11: 2.63 | J11: 33.46 | K11: 0.61 | L11: =COUNTIFS(Readings!$A$2:$A$2001,$A11,Readings!$C$2:$C$2001,"Live") -> 140 | M11: =COUNTIFS(Readings!$A$2:$A$2001,$A11,Readings!$C$2:$C$2001,"Live",Readings!$N$2:$N$2001,"normal") -> 93 | N11: =COUNTIFS(Readings!$A$2:$A$2001,$A11,Readings!$C$2:$C$2001,"Live",Readings!$N$2:$N$2001,"caution") -> 3 | O11: =COUNTIFS(Readings!$A$2:$A$2001,$A11,Readings!$C$2:$C$2001,"Live",Readings!$N$2:$N$2001,"alert") -> 44 | P11: =IF(L11=0,0,(N11+O11)/L11) -> 0.33571429 | Q11: =COUNTIFS(Readings!$A$2:$A$2001,$A11,Readings!$C$2:$C$2001,"Live",Readings!$M$2:$M$2001,">="&$B$2) -> 47 | R11: =COUNTIFS(Readings!$A$2:$A$2001,$A11,Readings!$C$2:$C$2001,"Live",Readings!$L$2:$L$2001,">="&$B$2) -> 44 | S11: =_xlfn.MAXIFS(Readings!$M$2:$M$2001,Readings!$A$2:$A$2001,$A11,Readings!$C$2:$C$2001,"Live") -> 6.4013841 | T11: =_xlfn.MAXIFS(Readings!$L$2:$L$2001,Readings!$A$2:$A$2001,$A11,Readings!$C$2:$C$2001,"Live") -> 6.295082 | U11: =IF(Q11>=$D$2,"Elevated","Normal") -> Elevated | V11: =IF(R11>=$D$2,"Elevated","Normal") -> Elevated | W11: =IF(AND(U11="Elevated",V11="Elevated"),"Both",IF(U11="Elevated","Pressure only",IF(V11="Elevated","Temperature only","No signs"))) -> Both | X11: =IF(W11=C11,"Yes","CHECK") -> Yes | Y11: =IF(O11>0,"alert",IF(N11>0,"caution","normal")) -> alert | Z11: =IF(W11="No signs","No meaningful deviation from own baseline during the live shift.","Deviation from own baseline: "&IF(U11="Elevated","pressure peaked "&TEXT(S11,"0.0")&" SD above own normal ("&Q11&" elevated readings)","")&IF(AND(U11="Elevated",V11="Elevated"),"; ","")&IF(V11="Elevated","temperature peaked "&TEXT(T11,"0.0")&" SD above own normal ("&R11&" elevated readings)","")&". "&O11&" alert and "&N11&" caution readings.") -> Deviation from own baseline: pressure peaked 6.4 SD above own normal (47 elevated readings); temperature peaked 6.3 SD above own normal (44 elevated readings). 44 alert and 3 caution readings.
A12: NURSE-08 | B12: Stable all shift, stays within own normal | C12: No signs | D12: 38.02 | E12: 2.8 | F12: 17.55 | G12: 1.97 | H12: 31.04 | I12: 2.94 | J12: 32.81 | K12: 0.58 | L12: =COUNTIFS(Readings!$A$2:$A$2001,$A12,Readings!$C$2:$C$2001,"Live") -> 140 | M12: =COUNTIFS(Readings!$A$2:$A$2001,$A12,Readings!$C$2:$C$2001,"Live",Readings!$N$2:$N$2001,"normal") -> 140 | N12: =COUNTIFS(Readings!$A$2:$A$2001,$A12,Readings!$C$2:$C$2001,"Live",Readings!$N$2:$N$2001,"caution") -> 0 | O12: =COUNTIFS(Readings!$A$2:$A$2001,$A12,Readings!$C$2:$C$2001,"Live",Readings!$N$2:$N$2001,"alert") -> 0 | P12: =IF(L12=0,0,(N12+O12)/L12) -> 0 | Q12: =COUNTIFS(Readings!$A$2:$A$2001,$A12,Readings!$C$2:$C$2001,"Live",Readings!$M$2:$M$2001,">="&$B$2) -> 0 | R12: =COUNTIFS(Readings!$A$2:$A$2001,$A12,Readings!$C$2:$C$2001,"Live",Readings!$L$2:$L$2001,">="&$B$2) -> 0 | S12: =_xlfn.MAXIFS(Readings!$M$2:$M$2001,Readings!$A$2:$A$2001,$A12,Readings!$C$2:$C$2001,"Live") -> 1.7785714 | T12: =_xlfn.MAXIFS(Readings!$L$2:$L$2001,Readings!$A$2:$A$2001,$A12,Readings!$C$2:$C$2001,"Live") -> 1.7068966 | U12: =IF(Q12>=$D$2,"Elevated","Normal") -> Normal | V12: =IF(R12>=$D$2,"Elevated","Normal") -> Normal | W12: =IF(AND(U12="Elevated",V12="Elevated"),"Both",IF(U12="Elevated","Pressure only",IF(V12="Elevated","Temperature only","No signs"))) -> No signs | X12: =IF(W12=C12,"Yes","CHECK") -> Yes | Y12: =IF(O12>0,"alert",IF(N12>0,"caution","normal")) -> normal | Z12: =IF(W12="No signs","No meaningful deviation from own baseline during the live shift.","Deviation from own baseline: "&IF(U12="Elevated","pressure peaked "&TEXT(S12,"0.0")&" SD above own normal ("&Q12&" elevated readings)","")&IF(AND(U12="Elevated",V12="Elevated"),"; ","")&IF(V12="Elevated","temperature peaked "&TEXT(T12,"0.0")&" SD above own normal ("&R12&" elevated readings)","")&". "&O12&" alert and "&N12&" caution readings.") -> No meaningful deviation from own baseline during the live shift.
A13: NURSE-09 | B13: Foot temperature drifts upward through the second half of the shift; pressure normal | C13: Temperature only | D13: 40.87 | E13: 2.9 | F13: 18.02 | G13: 2.02 | H13: 30.83 | I13: 3.22 | J13: 33.08 | K13: 0.61 | L13: =COUNTIFS(Readings!$A$2:$A$2001,$A13,Readings!$C$2:$C$2001,"Live") -> 140 | M13: =COUNTIFS(Readings!$A$2:$A$2001,$A13,Readings!$C$2:$C$2001,"Live",Readings!$N$2:$N$2001,"normal") -> 85 | N13: =COUNTIFS(Readings!$A$2:$A$2001,$A13,Readings!$C$2:$C$2001,"Live",Readings!$N$2:$N$2001,"caution") -> 55 | O13: =COUNTIFS(Readings!$A$2:$A$2001,$A13,Readings!$C$2:$C$2001,"Live",Readings!$N$2:$N$2001,"alert") -> 0 | P13: =IF(L13=0,0,(N13+O13)/L13) -> 0.39285714 | Q13: =COUNTIFS(Readings!$A$2:$A$2001,$A13,Readings!$C$2:$C$2001,"Live",Readings!$M$2:$M$2001,">="&$B$2) -> 0 | R13: =COUNTIFS(Readings!$A$2:$A$2001,$A13,Readings!$C$2:$C$2001,"Live",Readings!$L$2:$L$2001,">="&$B$2) -> 55 | S13: =_xlfn.MAXIFS(Readings!$M$2:$M$2001,Readings!$A$2:$A$2001,$A13,Readings!$C$2:$C$2001,"Live") -> 1.970297 | T13: =_xlfn.MAXIFS(Readings!$L$2:$L$2001,Readings!$A$2:$A$2001,$A13,Readings!$C$2:$C$2001,"Live") -> 5.7704918 | U13: =IF(Q13>=$D$2,"Elevated","Normal") -> Normal | V13: =IF(R13>=$D$2,"Elevated","Normal") -> Elevated | W13: =IF(AND(U13="Elevated",V13="Elevated"),"Both",IF(U13="Elevated","Pressure only",IF(V13="Elevated","Temperature only","No signs"))) -> Temperature only | X13: =IF(W13=C13,"Yes","CHECK") -> Yes | Y13: =IF(O13>0,"alert",IF(N13>0,"caution","normal")) -> caution | Z13: =IF(W13="No signs","No meaningful deviation from own baseline during the live shift.","Deviation from own baseline: "&IF(U13="Elevated","pressure peaked "&TEXT(S13,"0.0")&" SD above own normal ("&Q13&" elevated readings)","")&IF(AND(U13="Elevated",V13="Elevated"),"; ","")&IF(V13="Elevated","temperature peaked "&TEXT(T13,"0.0")&" SD above own normal ("&R13&" elevated readings)","")&". "&O13&" alert and "&N13&" caution readings.") -> Deviation from own baseline: temperature peaked 5.8 SD above own normal (55 elevated readings). 0 alert and 55 caution readings.
A14: NURSE-10 | B14: Mild rise in both pressure and temperature | C14: Both | D14: 42.98 | E14: 2.87 | F14: 20.29 | G14: 2.05 | H14: 29.87 | I14: 3.04 | J14: 32.98 | K14: 0.59 | L14: =COUNTIFS(Readings!$A$2:$A$2001,$A14,Readings!$C$2:$C$2001,"Live") -> 140 | M14: =COUNTIFS(Readings!$A$2:$A$2001,$A14,Readings!$C$2:$C$2001,"Live",Readings!$N$2:$N$2001,"normal") -> 122 | N14: =COUNTIFS(Readings!$A$2:$A$2001,$A14,Readings!$C$2:$C$2001,"Live",Readings!$N$2:$N$2001,"caution") -> 7 | O14: =COUNTIFS(Readings!$A$2:$A$2001,$A14,Readings!$C$2:$C$2001,"Live",Readings!$N$2:$N$2001,"alert") -> 11 | P14: =IF(L14=0,0,(N14+O14)/L14) -> 0.12857143 | Q14: =COUNTIFS(Readings!$A$2:$A$2001,$A14,Readings!$C$2:$C$2001,"Live",Readings!$M$2:$M$2001,">="&$B$2) -> 17 | R14: =COUNTIFS(Readings!$A$2:$A$2001,$A14,Readings!$C$2:$C$2001,"Live",Readings!$L$2:$L$2001,">="&$B$2) -> 13 | S14: =_xlfn.MAXIFS(Readings!$M$2:$M$2001,Readings!$A$2:$A$2001,$A14,Readings!$C$2:$C$2001,"Live") -> 4.0487805 | T14: =_xlfn.MAXIFS(Readings!$L$2:$L$2001,Readings!$A$2:$A$2001,$A14,Readings!$C$2:$C$2001,"Live") -> 3.9322034 | U14: =IF(Q14>=$D$2,"Elevated","Normal") -> Elevated | V14: =IF(R14>=$D$2,"Elevated","Normal") -> Elevated | W14: =IF(AND(U14="Elevated",V14="Elevated"),"Both",IF(U14="Elevated","Pressure only",IF(V14="Elevated","Temperature only","No signs"))) -> Both | X14: =IF(W14=C14,"Yes","CHECK") -> Yes | Y14: =IF(O14>0,"alert",IF(N14>0,"caution","normal")) -> alert | Z14: =IF(W14="No signs","No meaningful deviation from own baseline during the live shift.","Deviation from own baseline: "&IF(U14="Elevated","pressure peaked "&TEXT(S14,"0.0")&" SD above own normal ("&Q14&" elevated readings)","")&IF(AND(U14="Elevated",V14="Elevated"),"; ","")&IF(V14="Elevated","temperature peaked "&TEXT(T14,"0.0")&" SD above own normal ("&R14&" elevated readings)","")&". "&O14&" alert and "&N14&" caution readings.") -> Deviation from own baseline: pressure peaked 4.0 SD above own normal (17 elevated readings); temperature peaked 3.9 SD above own normal (13 elevated readings). 11 alert and 7 caution readings.
A17: Cohort overview
A18: Nurses in cohort | B18: =COUNTA(A5:A14) -> 10
A19: No signs | B19: =COUNTIF(W5:W14,"No signs") -> 3
A20: Pressure only | B20: =COUNTIF(W5:W14,"Pressure only") -> 2
A21: Temperature only | B21: =COUNTIF(W5:W14,"Temperature only") -> 2
A22: Both pressure and temperature | B22: =COUNTIF(W5:W14,"Both") -> 3
A23: Detected category matches design | B23: =COUNTIF(X5:X14,"Yes")&" of "&COUNTA(A5:A14) -> 10 of 10
A24: Total caution readings | B24: =SUM(N5:N14) -> 115
A25: Total alert readings | B25: =SUM(O5:O14) -> 81

Sheet Readings
A1: Nurse ID | B1: Timestamp | C1: Phase | D1: Heel pressure | E1: Midfoot pressure | F1: Toe pressure | G1: Temperature (°C) | H1: Motion state | I1: Heel deviation (SD) | J1: Midfoot deviation (SD) | K1: Toe deviation (SD) | L1: Temp deviation (SD) | M1: Max pressure deviation (SD) | N1: Risk level (ML module) | O1: Reason (ML module) | P1: Lookup key
A2: NURSE-01 | B2: 46303.292 | C2: Calibration | D2: 38.2 | E2: 16.1 | F2: 31.5 | G2: 32.1 | H2: sitting | I2: =(D2-INDEX('Cohort Summary'!$D$5:$D$14,MATCH($A2,'Cohort Summary'!$A$5:$A$14,0)))/INDEX('Cohort Summary'!$E$5:$E$14,MATCH($A2,'Cohort Summary'!$A$5:$A$14,0)) -> -0.58842444 | J2: =(E2-INDEX('Cohort Summary'!$F$5:$F$14,MATCH($A2,'Cohort Summary'!$A$5:$A$14,0)))/INDEX('Cohort Summary'!$G$5:$G$14,MATCH($A2,'Cohort Summary'!$A$5:$A$14,0)) -> -1.2525773 | K2: =(F2-INDEX('Cohort Summary'!$H$5:$H$14,MATCH($A2,'Cohort Summary'!$A$5:$A$14,0)))/INDEX('Cohort Summary'!$I$5:$I$14,MATCH($A2,'Cohort Summary'!$A$5:$A$14,0)) -> 0.48627451 | L2: =(G2-INDEX('Cohort Summary'!$J$5:$J$14,MATCH($A2,'Cohort Summary'!$A$5:$A$14,0)))/INDEX('Cohort Summary'!$K$5:$K$14,MATCH($A2,'Cohort Summary'!$A$5:$A$14,0)) -> -1.5272727 | M2: =MAX(I2:K2) -> 0.48627451 | N2: normal | P2: =A2&"|"&N2 -> NURSE-01|normal
A3: NURSE-01 | B3: 46303.292 | C3: Calibration | D3: 35.9 | E3: 19.1 | F3: 34.1 | G3: 32.4 | H3: standing | I3: =(D3-INDEX('Cohort Summary'!$D$5:$D$14,MATCH($A3,'Cohort Summary'!$A$5:$A$14,0)))/INDEX('Cohort Summary'!$E$5:$E$14,MATCH($A3,'Cohort Summary'!$A$5:$A$14,0)) -> -1.3279743 | J3: =(E3-INDEX('Cohort Summary'!$F$5:$F$14,MATCH($A3,'Cohort Summary'!$A$5:$A$14,0)))/INDEX('Cohort Summary'!$G$5:$G$14,MATCH($A3,'Cohort Summary'!$A$5:$A$14,0)) -> 0.29381443 | K3: =(F3-INDEX('Cohort Summary'!$H$5:$H$14,MATCH($A3,'Cohort Summary'!$A$5:$A$14,0)))/INDEX('Cohort Summary'!$I$5:$I$14,MATCH($A3,'Cohort Summary'!$A$5:$A$14,0)) -> 1.5058824 | L3: =(G3-INDEX('Cohort Summary'!$J$5:$J$14,MATCH($A3,'Cohort Summary'!$A$5:$A$14,0)))/INDEX('Cohort Summary'!$K$5:$K$14,MATCH($A3,'Cohort Summary'!$A$5:$A$14,0)) -> -0.98181818 | M3: =MAX(I3:K3) -> 1.5058824 | N3: normal | P3: =A3&"|"&N3 -> NURSE-01|normal
A4: NURSE-01 | B4: 46303.292 | C4: Calibration | D4: 39.3 | E4: 15.5 | F4: 25.9 | G4: 32.8 | H4: sitting | I4: =(D4-INDEX('Cohort Summary'!$D$5:$D$14,MATCH($A4,'Cohort Summary'!$A$5:$A$14,0)))/INDEX('Cohort Summary'!$E$5:$E$14,MATCH($A4,'Cohort Summary'!$A$5:$A$14,0)) -> -0.23472669 | J4: =(E4-INDEX('Cohort Summary'!$F$5:$F$14,MATCH($A4,'Cohort Summary'!$A$5:$A$14,0)))/INDEX('Cohort Summary'!$G$5:$G$14,MATCH($A4,'Cohort Summary'!$A$5:$A$14,0)) -> -1.5618557 | K4: =(F4-INDEX('Cohort Summary'!$H$5:$H$14,MATCH($A4,'Cohort Summary'!$A$5:$A$14,0)))/INDEX('Cohort Summary'!$I$5:$I$14,MATCH($A4,'Cohort Summary'!$A$5:$A$14,0)) -> -1.7098039 | L4: =(G4-INDEX('Cohort Summary'!$J$5:$J$14,MATCH($A4,'Cohort Summary'!$A$5:$A$14,0)))/INDEX('Cohort Summary'!$K$5:$K$14,MATCH($A4,'Cohort Summary'!$A$5:$A$14,0)) -> -0.25454545 | M4: =MAX(I4:K4) -> -0.23472669 | N4: normal | P4: =A4&"|"&N4 -> NURSE-01|normal
A5: NURSE-01 | B5: 46303.293 | C5: Calibration | D5: 36.2 | E5: 16.6 | F5: 31.3 | G5: 33.9 | H5: sitting | I5: =(D5-INDEX('Cohort Summary'!$D$5:$D$14,MATCH($A5,'Cohort Summary'!$A$5:$A$14,0)))/INDEX('Cohort Summary'!$E$5:$E$14,MATCH($A5,'Cohort Summary'!$A$5:$A$14,0)) -> -1.2315113 | J5: =(E5-INDEX('Cohort Summary'!$F$5:$F$14,MATCH($A5,'Cohort Summary'!$A$5:$A$14,0)))/INDEX('Cohort Summary'!$G$5:$G$14,MATCH($A5,'Cohort Summary'!$A$5:$A$14,0)) -> -0.99484536 | K5: =(F5-INDEX('Cohort Summary'!$H$5:$H$14,MATCH($A5,'Cohort Summary'!$A$5:$A$14,0)))/INDEX('Cohort Summary'!$I$5:$I$14,MATCH($A5,'Cohort Summary'!$A$5:$A$14,0)) -> 0.40784314 | L5: =(G5-INDEX('Cohort Summary'!$J$5:$J$14,MATCH($A5,'Cohort Summary'!$A$5:$A$14,0)))/INDEX('Cohort Summary'!$K$5:$K$14,MATCH($A5,'Cohort Summary'!$A$5:$A$14,0)) -> 1.7454545 | M5: =MAX(I5:K5) -> 0.40784314 | N5: normal | P5: =A5&"|"&N5 -> NURSE-01|normal
A6: NURSE-01 | B6: 46303.293 | C6: Calibration | D6: 40.9 | E6: 15.3 | F6: 27.2 | G6: 33.1 | H6: standing | I6: =(D6-INDEX('Cohort Summary'!$D$5:$D$14,MATCH($A6,'Cohort Summary'!$A$5:$A$14,0)))/INDEX('Cohort Summary'!$E$5:$E$14,MATCH($A6,'Cohort Summary'!$A$5:$A$14,0)) -> 0.27974277 | J6: =(E6-INDEX('Cohort Summary'!$F$5:$F$14,MATCH($A6,'Cohort Summary'!$A$5:$A$14,0)))/INDEX('Cohort Summary'!$G$5:$G$14,MATCH($A6,'Cohort Summary'!$A$5:$A$14,0)) -> -1.6649485 | K6: =(F6-INDEX('Cohort Summary'!$H$5:$H$14,MATCH($A6,'Cohort Summary'!$A$5:$A$14,0)))/INDEX('Cohort Summary'!$I$5:$I$14,MATCH($A6,'Cohort Summary'!$A$5:$A$14,0)) -> -1.2 | L6: =(G6-INDEX('Cohort Summary'!$J$5:$J$14,MATCH($A6,'Cohort Summary'!$A$5:$A$14,0)))/INDEX('Cohort Summary'!$K$5:$K$14,MATCH($A6,'Cohort Summary'!$A$5:$A$14,0)) -> 0.29090909 | M6: =MAX(I6:K6) -> 0.27974277 | N6: normal | P6: =A6&"|"&N6 -> NURSE-01|normal
A7: NURSE-01 | B7: 46303.293 | C7: Calibration | D7: 37.9 | E7: 16 | F7: 26.2 | G7: 32.6 | H7: sitting | I7: =(D7-INDEX('Cohort Summary'!$D$5:$D$14,MATCH($A7,'Cohort Summary'!$A$5:$A$14,0)))/INDEX('Cohort Summary'!$E$5:$E$14,MATCH($A7,'Cohort Summary'!$A$5:$A$14,0)) -> -0.68488746 | J7: =(E7-INDEX('Cohort Summary'!$F$5:$F$14,MATCH($A7,'Cohort Summary'!$A$5:$A$14,0)))/INDEX('Cohort Summary'!$G$5:$G$14,MATCH($A7,'Cohort Summary'!$A$5:$A$14,0)) -> -1.3041237 | K7: =(F7-INDEX('Cohort Summary'!$H$5:$H$14,MATCH($A7,'Cohort Summary'!$A$5:$A$14,0)))/INDEX('Cohort Summary'!$I$5:$I$14,MATCH($A7,'Cohort Summary'!$A$5:$A$14,0)) -> -1.5921569 | L7: =(G7-INDEX('Cohort Summary'!$J$5:$J$14,MATCH($A7,'Cohort Summary'!$A$5:$A$14,0)))/INDEX('Cohort Summary'!$K$5:$K$14,MATCH($A7,'Cohort Summary'!$A$5:$A$14,0)) -> -0.61818182 | M7: =MAX(I7:K7) -> -0.68488746 | N7: normal | P7: =A7&"|"&N7 -> NURSE-01|normal
A8: NURSE-01 | B8: 46303.294 | C8: Calibration | D8: 36.8 | E8: 19.1 | F8: 31.4 | G8: 32.7 | H8: sitting | I8: =(D8-INDEX('Cohort Summary'!$D$5:$D$14,MATCH($A8,'Cohort Summary'!$A$5:$A$14,0)))/INDEX('Cohort Summary'!$E$5:$E$14,MATCH($A8,'Cohort Summary'!$A$5:$A$14,0)) -> -1.0385852 | J8: =(E8-INDEX('Cohort Summary'!$F$5:$F$14,MATCH($A8,'Cohort Summary'!$A$5:$A$14,0)))/INDEX('Cohort Summary'!$G$5:$G$14,MATCH($A8,'Cohort Summary'!$A$5:$A$14,0)) -> 0.29381443 | K8: =(F8-INDEX('Cohort Summary'!$H$5:$H$14,MATCH($A8,'Cohort Summary'!$A$5:$A$14,0)))/INDEX('Cohort Summary'!$I$5:$I$14,MATCH($A8,'Cohort Summary'!$A$5:$A$14,0)) -> 0.44705882 | L8: =(G8-INDEX('Cohort Summary'!$J$5:$J$14,MATCH($A8,'Cohort Summary'!$A$5:$A$14,0)))/INDEX('Cohort Summary'!$K$5:$K$14,MATCH($A8,'Cohort Summary'!$A$5:$A$14,0)) -> -0.43636364 | M8: =MAX(I8:K8) -> 0.44705882 | N8: normal | P8: =A8&"|"&N8 -> NURSE-01|normal
A9: NURSE-01 | B9: 46303.294 | C9: Calibration | D9: 42.1 | E9: 19 | F9: 31.2 | G9: 33 | H9: sitting | I9: =(D9-INDEX('Cohort Summary'!$D$5:$D$14,MATCH($A9,'Cohort Summary'!$A$5:$A$14,0)))/INDEX('Cohort Summary'!$E$5:$E$14,MATCH($A9,'Cohort Summary'!$A$5:$A$14,0)) -> 0.66559486 | J9: =(E9-INDEX('Cohort Summary'!$F$5:$F$14,MATCH($A9,'Cohort Summary'!$A$5:$A$14,0)))/INDEX('Cohort Summary'!$G$5:$G$14,MATCH($A9,'Cohort Summary'!$A$5:$A$14,0)) -> 0.24226804 | K9: =(F9-INDEX('Cohort Summary'!$H$5:$H$14,MATCH($A9,'Cohort Summary'!$A$5:$A$14,0)))/INDEX('Cohort Summary'!$I$5:$I$14,MATCH($A9,'Cohort Summary'!$A$5:$A$14,0)) -> 0.36862745 | L9: =(G9-INDEX('Cohort Summary'!$J$5:$J$14,MATCH($A9,'Cohort Summary'!$A$5:$A$14,0)))/INDEX('Cohort Summary'!$K$5:$K$14,MATCH($A9,'Cohort Summary'!$A$5:$A$14,0)) -> 0.10909091 | M9: =MAX(I9:K9) -> 0.66559486 | N9: normal | P9: =A9&"|"&N9 -> NURSE-01|normal
A10: NURSE-01 | B10: 46303.294 | C10: Calibration | D10: 39.3 | E10: 17.2 | F10: 30.9 | G10: 32.9 | H10: walking | I10: =(D10-INDEX('Cohort Summary'!$D$5:$D$14,MATCH($A10,'Cohort Summary'!$A$5:$A$14,0)))/INDEX('Cohort Summary'!$E$5:$E$14,MATCH($A10,'Cohort Summary'!$A$5:$A$14,0)) -> -0.23472669 | J10: =(E10-INDEX('Cohort Summary'!$F$5:$F$14,MATCH($A10,'Cohort Summary'!$A$5:$A$14,0)))/INDEX('Cohort Summary'!$G$5:$G$14,MATCH($A10,'Cohort Summary'!$A$5:$A$14,0)) -> -0.68556701 | K10: =(F10-INDEX('Cohort Summary'!$H$5:$H$14,MATCH($A10,'Cohort Summary'!$A$5:$A$14,0)))/INDEX('Cohort Summary'!$I$5:$I$14,MATCH($A10,'Cohort Summary'!$A$5:$A$14,0)) -> 0.25098039 | L10: =(G10-INDEX('Cohort Summary'!$J$5:$J$14,MATCH($A10,'Cohort Summary'!$A$5:$A$14,0)))/INDEX('Cohort Summary'!$K$5:$K$14,MATCH($A10,'Cohort Summary'!$A$5:$A$14,0)) -> -0.072727273 | M10: =MAX(I10:K10) -> 0.25098039 | N10: normal | P10: =A10&"|"&N10 -> NURSE-01|normal
A11: NURSE-01 | B11: 46303.295 | C11: Calibration | D11: 37.5 | E11: 16.3 | F11: 32.8 | G11: 32.2 | H11: walking | I11: =(D11-INDEX('Cohort Summary'!$D$5:$D$14,MATCH($A11,'Cohort Summary'!$A$5:$A$14,0)))/INDEX('Cohort Summary'!$E$5:$E$14,MATCH($A11,'Cohort Summary'!$A$5:$A$14,0)) -> -0.81350482 | J11: =(E11-INDEX('Cohort Summary'!$F$5:$F$14,MATCH($A11,'Cohort Summary'!$A$5:$A$14,0)))/INDEX('Cohort Summary'!$G$5:$G$14,MATCH($A11,'Cohort Summary'!$A$5:$A$14,0)) -> -1.1494845 | K11: =(F11-INDEX('Cohort Summary'!$H$5:$H$14,MATCH($A11,'Cohort Summary'!$A$5:$A$14,0)))/INDEX('Cohort Summary'!$I$5:$I$14,MATCH($A11,'Cohort Summary'!$A$5:$A$14,0)) -> 0.99607843 | L11: =(G11-INDEX('Cohort Summary'!$J$5:$J$14,MATCH($A11,'Cohort Summary'!$A$5:$A$14,0)))/INDEX('Cohort Summary'!$K$5:$K$14,MATCH($A11,'Cohort Summary'!$A$5:$A$14,0)) -> -1.3454545 | M11: =MAX(I11:K11) -> 0.99607843 | N11: normal | P11: =A11&"|"&N11 -> NURSE-01|normal
A12: NURSE-01 | B12: 46303.295 | C12: Calibration | D12: 40.3 | E12: 21.1 | F12: 32.3 | G12: 32.6 | H12: standing | I12: =(D12-INDEX('Cohort Summary'!$D$5:$D$14,MATCH($A12,'Cohort Summary'!$A$5:$A$14,0)))/INDEX('Cohort Summary'!$E$5:$E$14,MATCH($A12,'Cohort Summary'!$A$5:$A$14,0)) -> 0.08681672 | J12: =(E12-INDEX('Cohort Summary'!$F$5:$F$14,MATCH($A12,'Cohort Summary'!$A$5:$A$14,0)))/INDEX('Cohort Summary'!$G$5:$G$14,MATCH($A12,'Cohort Summary'!$A$5:$A$14,0)) -> 1.3247423 | K12: =(F12-INDEX('Cohort Summary'!$H$5:$H$14,MATCH($A12,'Cohort Summary'!$A$5:$A$14,0)))/INDEX('Cohort Summary'!$I$5:$I$14,MATCH($A12,'Cohort Summary'!$A$5:$A$14,0)) -> 0.8 | L12: =(G12-INDEX('Cohort Summary'!$J$5:$J$14,MATCH($A12,'Cohort Summary'!$A$5:$A$14,0)))/INDEX('Cohort Summary'!$K$5:$K$14,MATCH($A12,'Cohort Summary'!$A$5:$A$14,0)) -> -0.61818182 | M12: =MAX(I12:K12) -> 1.3247423 | N12: normal | P12: =A12&"|"&N12 -> NURSE-01|normal
A13: NURSE-01 | B13: 46303.295 | C13: Calibration | D13: 36.2 | E13: 17.9 | F13: 32.6 | G13: 32.3 | H13: walking | I13: =(D13-INDEX('Cohort Summary'!$D$5:$D$14,MATCH($A13,'Cohort Summary'!$A$5:$A$14,0)))/INDEX('Cohort Summary'!$E$5:$E$14,MATCH($A13,'Cohort Summary'!$A$5:$A$14,0)) -> -1.2315113 | J13: =(E13-INDEX('Cohort Summary'!$F$5:$F$14,MATCH($A13,'Cohort Summary'!$A$5:$A$14,0)))/INDEX('Cohort Summary'!$G$5:$G$14,MATCH($A13,'Cohort Summary'!$A$5:$A$14,0)) -> -0.32474227 | K13: =(F13-INDEX('Cohort Summary'!$H$5:$H$14,MATCH($A13,'Cohort Summary'!$A$5:$A$14,0)))/INDEX('Cohort Summary'!$I$5:$I$14,MATCH($A13,'Cohort Summary'!$A$5:$A$14,0)) -> 0.91764706 | L13: =(G13-INDEX('Cohort Summary'!$J$5:$J$14,MATCH($A13,'Cohort Summary'!$A$5:$A$14,0)))/INDEX('Cohort Summary'!$K$5:$K$14,MATCH($A13,'Cohort Summary'!$A$5:$A$14,0)) -> -1.1636364 | M13: =MAX(I13:K13) -> 0.91764706 | N13: normal | P13: =A13&"|"&N13 -> NURSE-01|normal
... A274: NURSE-02 | B274: 46303.317 | C274: Live | D274: 49.1 | E274: 17.8 | F274: 36 | G274: 32.8 | H274: standing | I274: =(D274-INDEX('Cohort Summary'!$D$5:$D$14,MATCH($A274,'Cohort Summary'!$A$5:$A$14,0)))/INDEX('Cohort Summary'!$E$5:$E$14,MATCH($A274,'Cohort Summary'!$A$5:$A$14,0)) -> 1.6226994 | J274: =(E274-INDEX('Cohort Summary'!$F$5:$F$14,MATCH($A274,'Cohort Summary'!$A$5:$A$14,0)))/INDEX('Cohort Summary'!$G$5:$G$14,MATCH($A274,'Cohort Summary'!$A$5:$A$14,0)) -> -0.58962264 | K274: =(F274-INDEX('Cohort Summary'!$H$5:$H$14,MATCH($A274,'Cohort Summary'!$A$5:$A$14,0)))/INDEX('Cohort Summary'!$I$5:$I$14,MATCH($A274,'Cohort Summary'!$A$5:$A$14,0)) -> 1.207483 | L274: =(G274-INDEX('Cohort Summary'!$J$5:$J$14,MATCH($A274,'Cohort Summary'!$A$5:$A$14,0)))/INDEX('Cohort Summary'!$K$5:$K$14,MATCH($A274,'Cohort Summary'!$A$5:$A$14,0)) -> -0.046875 | M274: =MAX(I274:K274) -> 1.6226994 | N274: normal | P274: =A274&"|"&N274 -> NURSE-02|normal
A275: NURSE-02 | B275: 46303.317 | C275: Live | D275: 56.8 | E275: 20.4 | F275: 36.4 | G275: 32.1 | H275: standing | I275: =(D275-INDEX('Cohort Summary'!$D$5:$D$14,MATCH($A275,'Cohort Summary'!$A$5:$A$14,0)))/INDEX('Cohort Summary'!$E$5:$E$14,MATCH($A275,'Cohort Summary'!$A$5:$A$14,0)) -> 3.9846626 | J275: =(E275-INDEX('Cohort Summary'!$F$5:$F$14,MATCH($A275,'Cohort Summary'!$A$5:$A$14,0)))/INDEX('Cohort Summary'!$G$5:$G$14,MATCH($A275,'Cohort Summary'!$A$5:$A$14,0)) -> 0.63679245 | K275: =(F275-INDEX('Cohort Summary'!$H$5:$H$14,MATCH($A275,'Cohort Summary'!$A$5:$A$14,0)))/INDEX('Cohort Summary'!$I$5:$I$14,MATCH($A275,'Cohort Summary'!$A$5:$A$14,0)) -> 1.3435374 | L275: =(G275-INDEX('Cohort Summary'!$J$5:$J$14,MATCH($A275,'Cohort Summary'!$A$5:$A$14,0)))/INDEX('Cohort Summary'!$K$5:$K$14,MATCH($A275,'Cohort Summary'!$A$5:$A$14,0)) -> -1.140625 | M275: =MAX(I275:K275) -> 3.9846626 | N275: caution | O275: heel pressure 4.0 SD above personal baseline | P275: =A275&"|"&N275 -> NURSE-02|caution
A276: NURSE-02 | B276: 46303.317 | C276: Live | D276: 54.5 | E276: 21.3 | F276: 33.5 | G276: 32.5 | H276: standing | I276: =(D276-INDEX('Cohort Summary'!$D$5:$D$14,MATCH($A276,'Cohort Summary'!$A$5:$A$14,0)))/INDEX('Cohort Summary'!$E$5:$E$14,MATCH($A276,'Cohort Summary'!$A$5:$A$14,0)) -> 3.2791411 | J276: =(E276-INDEX('Cohort Summary'!$F$5:$F$14,MATCH($A276,'Cohort Summary'!$A$5:$A$14,0)))/INDEX('Cohort Summary'!$G$5:$G$14,MATCH($A276,'Cohort Summary'!$A$5:$A$14,0)) -> 1.0613208 | K276: =(F276-INDEX('Cohort Summary'!$H$5:$H$14,MATCH($A276,'Cohort Summary'!$A$5:$A$14,0)))/INDEX('Cohort Summary'!$I$5:$I$14,MATCH($A276,'Cohort Summary'!$A$5:$A$14,0)) -> 0.35714286 | L276: =(G276-INDEX('Cohort Summary'!$J$5:$J$14,MATCH($A276,'Cohort Summary'!$A$5:$A$14,0)))/INDEX('Cohort Summary'!$K$5:$K$14,MATCH($A276,'Cohort Summary'!$A$5:$A$14,0)) -> -0.515625 | M276: =MAX(I276:K276) -> 3.2791411 | N276: caution | O276: heel pressure 3.3 SD above personal baseline | P276: =A276&"|"&N276 -> NURSE-02|caution
A277: NURSE-02 | B277: 46303.318 | C277: Live | D277: 52.2 | E277: 22.1 | F277: 31.5 | G277: 32.9 | H277: standing | I277: =(D277-INDEX('Cohort Summary'!$D$5:$D$14,MATCH($A277,'Cohort Summary'!$A$5:$A$14,0)))/INDEX('Cohort Summary'!$E$5:$E$14,MATCH($A277,'Cohort Summary'!$A$5:$A$14,0)) -> 2.5736196 | J277: =(E277-INDEX('Cohort Summary'!$F$5:$F$14,MATCH($A277,'Cohort Summary'!$A$5:$A$14,0)))/INDEX('Cohort Summary'!$G$5:$G$14,MATCH($A277,'Cohort Summary'!$A$5:$A$14,0)) -> 1.4386792 | K277: =(F277-INDEX('Cohort Summary'!$H$5:$H$14,MATCH($A277,'Cohort Summary'!$A$5:$A$14,0)))/INDEX('Cohort Summary'!$I$5:$I$14,MATCH($A277,'Cohort Summary'!$A$5:$A$14,0)) -> -0.32312925 | L277: =(G277-INDEX('Cohort Summary'!$J$5:$J$14,MATCH($A277,'Cohort Summary'!$A$5:$A$14,0)))/INDEX('Cohort Summary'!$K$5:$K$14,MATCH($A277,'Cohort Summary'!$A$5:$A$14,0)) -> 0.109375 | M277: =MAX(I277:K277) -> 2.5736196 | N277: caution | O277: heel pressure 2.6 SD above personal baseline | P277: =A277&"|"&N277 -> NURSE-02|caution
A278: NURSE-02 | B278: 46303.318 | C278: Live | D278: 48.7 | E278: 19.1 | F278: 34.7 | G278: 33 | H278: standing | I278: =(D278-INDEX('Cohort Summary'!$D$5:$D$14,MATCH($A278,'Cohort Summary'!$A$5:$A$14,0)))/INDEX('Cohort Summary'!$E$5:$E$14,MATCH($A278,'Cohort Summary'!$A$5:$A$14,0)) -> 1.5 | J278: =(E278-INDEX('Cohort Summary'!$F$5:$F$14,MATCH($A278,'Cohort Summary'!$A$5:$A$14,0)))/INDEX('Cohort Summary'!$G$5:$G$14,MATCH($A278,'Cohort Summary'!$A$5:$A$14,0)) -> 0.023584906 | K278: =(F278-INDEX('Cohort Summary'!$H$5:$H$14,MATCH($A278,'Cohort Summary'!$A$5:$A$14,0)))/INDEX('Cohort Summary'!$I$5:$I$14,MATCH($A278,'Cohort Summary'!$A$5:$A$14,0)) -> 0.76530612 | L278: =(G278-INDEX('Cohort Summary'!$J$5:$J$14,MATCH($A278,'Cohort Summary'!$A$5:$A$14,0)))/INDEX('Cohort Summary'!$K$5:$K$14,MATCH($A278,'Cohort Summary'!$A$5:$A$14,0)) -> 0.265625 | M278: =MAX(I278:K278) -> 1.5 | N278: normal | P278: =A278&"|"&N278 -> NURSE-02|normal
A279: NURSE-02 | B279: 46303.318 | C279: Live | D279: 42.3 | E279: 20.5 | F279: 34 | G279: 32.8 | H279: walking | I279: =(D279-INDEX('Cohort Summary'!$D$5:$D$14,MATCH($A279,'Cohort Summary'!$A$5:$A$14,0)))/INDEX('Cohort Summary'!$E$5:$E$14,MATCH($A279,'Cohort Summary'!$A$5:$A$14,0)) -> -0.46319018 | J279: =(E279-INDEX('Cohort Summary'!$F$5:$F$14,MATCH($A279,'Cohort Summary'!$A$5:$A$14,0)))/INDEX('Cohort Summary'!$G$5:$G$14,MATCH($A279,'Cohort Summary'!$A$5:$A$14,0)) -> 0.68396226 | K279: =(F279-INDEX('Cohort Summary'!$H$5:$H$14,MATCH($A279,'Cohort Summary'!$A$5:$A$14,0)))/INDEX('Cohort Summary'!$I$5:$I$14,MATCH($A279,'Cohort Summary'!$A$5:$A$14,0)) -> 0.52721088 | L279: =(G279-INDEX('Cohort Summary'!$J$5:$J$14,MATCH($A279,'Cohort Summary'!$A$5:$A$14,0)))/INDEX('Cohort Summary'!$K$5:$K$14,MATCH($A279,'Cohort Summary'!$A$5:$A$14,0)) -> -0.046875 | M279: =MAX(I279:K279) -> 0.68396226 | N279: normal | P279: =A279&"|"&N279 -> NURSE-02|normal
A280: NURSE-02 | B280: 46303.319 | C280: Live | D280: 42 | E280: 20.9 | F280: 35.4 | G280: 32.1 | H280: standing | I280: =(D280-INDEX('Cohort Summary'!$D$5:$D$14,MATCH($A280,'Cohort Summary'!$A$5:$A$14,0)))/INDEX('Cohort Summary'!$E$5:$E$14,MATCH($A280,'Cohort Summary'!$A$5:$A$14,0)) -> -0.55521472 | J280: =(E280-INDEX('Cohort Summary'!$F$5:$F$14,MATCH($A280,'Cohort Summary'!$A$5:$A$14,0)))/INDEX('Cohort Summary'!$G$5:$G$14,MATCH($A280,'Cohort Summary'!$A$5:$A$14,0)) -> 0.87264151 | K280: =(F280-INDEX('Cohort Summary'!$H$5:$H$14,MATCH($A280,'Cohort Summary'!$A$5:$A$14,0)))/INDEX('Cohort Summary'!$I$5:$I$14,MATCH($A280,'Cohort Summary'!$A$5:$A$14,0)) -> 1.0034014 | L280: =(G280-INDEX('Cohort Summary'!$J$5:$J$14,MATCH($A280,'Cohort Summary'!$A$5:$A$14,0)))/INDEX('Cohort Summary'!$K$5:$K$14,MATCH($A280,'Cohort Summary'!$A$5:$A$14,0)) -> -1.140625 | M280: =MAX(I280:K280) -> 1.0034014 | N280: normal | P280: =A280&"|"&N280 -> NURSE-02|normal
